# 捕获和抛出异常

```java
package com.broky.exception;

public class Test {
    public static void main(String[] args) {
        int a = 1;
        int b = 0;

        //假设要捕获多个异常:从小到大
        //快捷键ctrl+alt+t
        try {

            if (b == 0) {
                throw new ArithmeticException();  //主动抛出异常
            }
            System.out.println(a / b);

        } catch (Error e) {
            System.out.println("Error");
        } catch (Exception e) {
            System.out.println("Exception");
        } catch (Throwable t) {
            System.out.println("Throwable");
        } finally {
            System.out.println("finally");
        }
        //finally 可以不要finally, 假设IO,资源,关闭!
        System.out.println("==========================================");

        try {
            System.out.println(a/b);
        } catch (Exception e) {
            e.printStackTrace();    //打印错误信息
            System.exit(0); //令程序结束
        } finally {
        }
    }

    //假设这方法中,处理不了这个异常. 方法上抛出异常
    public void test(int a,int b) throws ArithmeticException{
        if (b==0){
            throw new ArithmeticException();    //主动抛出异常, 一般在方法种使用
        }
    }

    public void a() {
        b();
    }

    public void b() {
        a();
    }
}
```

# 自定义一异常

```java
package com.broky.exception.demo02;

public class MyException extends Exception {

    private int detail;

    //传递数字>0
    public MyException(int a) {
        this.detail = a;
    }

    //toString:异常的打印信息

    @Override
    public String toString() {
        return "MyException{\n" +
                "detail=" + detail +
                "\n输入的数字大于10" +
                '}';
    }
}
```

```java
package com.broky.exception.demo02;

//自定义异常类
public class Test {
    static void test(int a) throws MyException {
        if (a > 10) {
            throw new MyException(a);
        }
        System.out.println("OK");
    }

    public static void main(String[] args) {
        try {
            test(11);
        } catch (MyException e) {
            // 对异常进行处理
            e.printStackTrace();    //此处是默认的异常处理, 打印出异常的情况
        }
    }
    /*
    先运行try, 调用了test方法, 传入了数字11
    由于11 大于10 所以test会抛出一个异常
    异常抛出后被catch捕获
    之后打印异常
     */
}
```

- 总结

  ◆处理运行时异常时,采用逻辑去合理规避同时辅助try- catch处理
  ◆在多重 catch块后面,可以加一个 catch( Exception)来处理可能会被遗漏的异常
  ◆对于不确定的代码,也可以加上try- catch,处理潜在的异常
  ◆尽量去处理异常,切忌只是简单地调用 printStackTrace0去打印输出
  ◆具体如何处理异常,要根据不同的业务需求和异常类型去决定
  ◆尽量添加 Finally语句块去释放占用的资源.